Workbook

Sheet Trường hợp kiểm thử
A1: TEST CASE SYSTEM SPRINT 2
A3: Tên dự án | B3: CoffeeGo-Nền tảng đặt bàn quán cà phê tích hợp AI Assistant và thanh toán điện tử
A4: STT | B4: Chức năng | C4: Sheet Name | D4: Số test case | E4: Mô tả
A5: 1 | B5: Giỏ hàng | C5: Giỏ hàng | D5: ='Giỏ hàng'!B4 -> 37
A6: 2 | B6: Đặt bàn | C6: Đặt bàn | D6: ='Đặt bàn'!B4 -> 31
A7: 3 | B7: Order | C7: Order | D7: =Order!B4 -> 23
A8: 4 | B8: Lịch sử đặt hàng | C8: Lịch sử đặt hàng | D8: ='Lịch sử đặt hàng'!B4 -> 19
A9: 5 | B9: Quản lý đặt bàn | C9: Quản lý đặt bàn | D9: ='Quản lý đặt bàn'!B4 -> 15
A10: 6 | B10: Quản lý khuyến mãi | C10: Danh sách khuyến mãi | D10: ='Danh sách khuyến mãi'!B4 -> 13
C11: Thêm khuyến mãi | D11: ='Thêm khuyến mãi'!B4 -> 31
A12: 7 | B12: Quản lý đặt hàng | C12: Quản lý đặt hàng | D12: ='Quản lý đặt hàng'!B4 -> 12
A13: 8 | B13: Quản lý thống kê | C13: Thống kê | D13: ='Thống kê '!B4 -> 12
A14: 9 | B14: Quản lý kho | C14: Danh sách kho | D14: ='Danh sách kho '!B4 -> 15
C15: Thêm nguyên liệu | D15: ='Thêm nguyên liệu'!B4 -> 12
C16: Cập nhật nguyên liệu | D16: ='Cập nhật nguyên liệu'!B4 -> 12
A17: 10 | B17: Quản lý phiếu nhập kho | C17: Quản lý phiếu nhập kho | D17: ='Quản lý phiếu nhập kho'!B4 -> 10
C18: Tạo phiếu nhập kho | D18: ='Tạo phiếu nhập kho'!B4 -> 18
C19: Tổng: | D19: =SUM(D5:D18) -> 260

Sheet Giỏ hàng
A1: Project Name | B1: CoffeeGo-Nền tảng đặt bàn quán cà phê tích hợp AI Assistant và thanh toán điện tử
A2: Module Code | B2: Giỏ hàng
B3: Hoàn thành | C3: Lỗi | D3: Chưa kiểm tra | E3: Bị chặn | F3: Tổng lần kiểm tra
A4: Round 1 | B4: =COUNTA(A35:A72)- 1 -> 37 | C4: =COUNTIF(G:G,"Failed") -> 3 | D4: =COUNTIF(G:G,"Untested") -> 0 | E4: =COUNTIF(G:G,"Blocked") -> 0 | F4: =B4 -> 37
A5: Round 2 | B5: =COUNTA(A59:A72) -> 14 | C5: =COUNTIF(J:J,"Failed") -> 0 | D5: =COUNTIF(J:J,"Untested") -> 0 | E5: =COUNTIF(J:J,"Blocked") -> 0 | F5: =B5 -> 14
A31: Test Case ID | B31: Mô tả | C31: Quy trình | D31: Điều kiện tiên quyết | E31: Kết quả mong đợi | F31: Kết quả thực tế | G31: Kết quả | M31: Chú thích
G32: Vòng 1 | J32: Vòng 2
G33: Trạng thái | H33: Ngày kiểm tra | I33: Người kiểm tra | J33: Trạng thái | K33: Ngày kiểm tra | L33: Người kiểm tra
A34: GUI_SHOW Giỏ hàng
A35: GUI - GH01 | B35: [Xác nhận đơn hàng] Label | E35: - Text: Black - Status: Enable | F35: - Text: Black - Status: Enable | G35: Passed | H35: 45983 | I35: Đức | J35: Passed
A36: GUI - GH02 | B36: [Giao hàng] Label | E36: - Text: Black - Status: Enable | F36: - Text: Black - Status: Enable | G36: Passed | H36: 45983 | I36: Đức | J36: Passed
A37: GUI - GH03 | B37: [Chú ý] Label | E37: - Text: Orange - Status: Enable | F37: - Text: Orange - Status: Enable | G37: Passed | H37: 45983 | I37: Đức | J37: Passed
A38: GUI - GH04 | B38: [Nhận hàng trong ngày 15-30 phút] Label | E38: - Text: Black - Status: Enable | F38: - Text: Black - Status: Enable | G38: Passed | H38: 45983 | I38: Đức | J38: Passed
A39: GUI - GH05 | B39: [Vào lúc] Label | E39: - Text: Black - Status: Enable | F39: - Text: Black - Status: Enable | G39: Passed | H39: 45983 | I39: Đức | J39: Passed
A40: GUI - GH06 | B40: [Vào lúc] Dropdown | E40: - Text: Black - Status: Enable - Default: Càng sớm càng tốt | F40: - Text: Black - Status: Enable - Default: Càng sớm càng tốt | G40: Passed | H40: 45983 | I40: Đức | J40: Passed
A41: GUI - GH07 | B41: [Cách nhận hàng] Label | E41: - Text: Black - Status: Enable | F41: - Text: Black - Status: Enable | G41: Passed | H41: 45983 | I41: Đức | J41: Passed
A42: GUI - GH08 | B42: [Cách nhận hàng] Dropdown | E42: - Text: Black - Status: Enable - Default: Giao tận nơi | F42: - Text: Black - Status: Enable - Default: Giao tận nơi | G42: Passed | H42: 45983 | I42: Đức | J42: Passed
A43: GUI - GH09 | B43: [Địa chỉ] Textbox | E43: - Text: Grey - Status: Enable | F43: - Text: Grey - Status: Enable | G43: Passed | H43: 45983 | I43: Đức | J43: Passed
A44: GUI - GH10 | B44: [Tên người nhận] Textbox | E44: - Text: Grey - Status: Enable - Default: Account name | F44: - Text: Grey - Status: Enable - Default: Account name | G44: Passed | H44: 45983 | I44: Đức | J44: Passed
A45: GUI - GH11 | B45: [Số điện thoại] Textbox | E45: - Text: Grey - Status: Enable | F45: - Text: Grey - Status: Enable | G45: Passed | H45: 45983 | I45: Đức | J45: Passed
A46: GUI - GH12 | B46: [Hướng dẫn giao hàng] Textbox | E46: - Text: Grey - Status: Enable | F46: - Text: Grey - Status: Enable | G46: Passed | H46: 45983 | I46: Đức | J46: Passed
... A57: GUI - GH23 | B57: [Đặt hàng] Button | E57: -Text color : orange -Status : Enable -Background-color : white | F57: -Text color : orange -Status : Enable -Background-color : white | G57: Passed | H57: 45983 | I57: Đức | J57: Passed
A58: FUNCTION_SHOW Giỏ hàng
A59: FUNC-GH01 | B59: Kiểm tra dropdown “Vào lúc” chỉ hiển thị các giờ sau thời gian hiện tại | C59: 1. Truy cập trang “Giỏ hàng” 2. Click dropdown “Vào lúc” 3. Kiểm tra danh sách giờ hiển thị | D59: Đăng nhập thành công vào hệ thống | E59: Dropdown chỉ hiển thị các khung giờ sau thời gian hiện tại | F59: Dropdown chỉ hiển thị các khung giờ sau thời gian hiện tại | G59: Passed | H59: 45983 | I59: Đức | J59: Passed | K59: 45987 | L59: Đức
A60: FUNC-GH02 | B60: Nhập địa chỉ giao hàng hợp lệ | C60: 1. Nhập textbox “Địa chỉ” = “123 Nguyễn Văn Cừ, Q5” 2. Click “Đặt hàng” | D60: Đăng nhập thành công vào hệ thống | E60: Hệ thống chấp nhận địa chỉ và tiếp tục xử lý đơn hàng | F60: Hệ thống chấp nhận địa chỉ và tiếp tục xử lý đơn hàng | G60: Passed | H60: 45983 | I60: Đức | J60: Passed | K60: 45987 | L60: Đức
A61: FUNC-GH03 | B61: Để trống địa chỉ giao hàng | C61: 1. Để trống textbox “Địa chỉ” 2. Click “Đặt hàng” | D61: Đăng nhập thành công vào hệ thống | E61: Hệ thống hiển thị cảnh báo “Chưa nhập địa chỉ” | F61: Hệ thống hiển thị cảnh báo “Chưa nhập địa chỉ” | G61: Passed | H61: 45983 | I61: Đức | J61: Passed | K61: 45987 | L61: Đức
A62: FUNC-GH04 | B62: Nhập số điện thoại hợp lệ | C62: 1. Nhập “0912345678” vào textbox “Số điện thoại” 2. Click “Đặt hàng” | D62: Đăng nhập thành công vào hệ thống | E62: Hệ thống chấp nhận số điện thoại | F62: Hệ thống chấp nhận số điện thoại | G62: Passed | H62: 45983 | I62: Đức | J62: Passed | K62: 45987 | L62: Đức
A63: FUNC-GH05 | B63: Nhập số điện thoại không hợp lệ | C63: 1. Nhập “abcd1234” vào textbox “Số điện thoại” 2. Click “Đặt hàng” | D63: Đăng nhập thành công vào hệ thống | E63: Hệ thống hiển thị cảnh báo “Số điện thoại không hợp lệ” | F63: Hệ thống hiển thị cảnh báo “Số điện thoại không hợp lệ” | G63: Passed | H63: 45983 | I63: Đức | J63: Passed | K63: 45987 | L63: Đức
A64: FUNC-GH06 | B64: Để trống số điện thoại | C64: 1. Để trống textbox “Số điện thoại” 2. Click “Đặt hàng” | D64: Đăng nhập thành công vào hệ thống | E64: Hệ thống hiển thị cảnh báo “Chưa nhập số điện thoại” | F64: Hệ thống không hiển thị cảnh báo “Chưa nhập số điện thoại” | G64: Failed | H64: 45983 | I64: Đức | J64: Passed | K64: 45987 | L64: Đức
A65: FUNC-GH07 | B65: Nhập hướng dẫn giao hàng | C65: 1. Nhập “Gọi trước khi giao” vào textbox “Hướng dẫn giao hàng” 2. Click “Đặt hàng” | D65: Đăng nhập thành công vào hệ thống | E65: Hệ thống chấp nhận nội dung | F65: Hệ thống chấp nhận nội dung | G65: Passed | H65: 45983 | I65: Đức | J65: Passed | K65: 45987 | L65: Đức
A66: FUNC-GH08 | B66: Thêm món vào giỏ | C66: 1. Click “Thêm món” | D66: Đăng nhập thành công vào hệ thống | E66: Chuyển sang trang menu | F66: Chuyển sang trang menu | G66: Passed | H66: 45983 | I66: Đức | J66: Passed | K66: 45987 | L66: Đức
A67: FUNC-GH09 | B67: Xóa món khỏi giỏ hàng | C67: 1. Nhấn icon Xóa trên 1 sản phẩm | D67: Có ít nhất 1 món trong giỏ | E67: Món biến mất khỏi giỏ | F67: Món không biến mất khỏi giỏ | G67: Failed | H67: 45983 | I67: Đức | J67: Passed | K67: 45987 | L67: Đức
A68: FUNC-GH10 | B68: Chỉnh sửa món trong giỏ hàng | C68: 1. Nhấn icon Chỉnh sửa | D68: Có ít nhất 1 món trong giỏ | E68: Điều hướng sang trang chỉnh sửa món | F68: Không điều hướng sang trang chỉnh sửa món | G68: Failed | H68: 45983 | I68: Đức | J68: Passed | K68: 45987 | L68: Đức
A69: FUNC-GH11 | B69: Kiểm tra “Thành tiền” tính đúng | C69: 1. Có 2 sản phẩm: 50k + 30k, ship 20k 2. Kiểm tra nhãn “Thành tiền” | D69: Có ít nhất 1 món trong giỏ | E69: 100000 | F69: 100000 | G69: Passed | H69: 45983 | I69: Đức | J69: Passed | K69: 45987 | L69: Đức
A70: FUNC-GH12 | B70: “Thành tiền” cập nhật sau khi xóa món | C70: 1. Xóa 1 món 2. Kiểm tra nhãn “Thành tiền” | D70: Có ít nhất 1 món trong giỏ | E70: Tổng tiền giảm đúng | F70: Tổng tiền giảm đúng | G70: Passed | H70: 45983 | I70: Đức | J70: Passed | K70: 45987 | L70: Đức
A71: FUNC-GH13 | B71: Đặt hàng thành công | C71: 1. Nhập tất cả thông tin hợp lệ 2. Click “Đặt hàng” | D71: Có ít nhất 1 món trong giỏ | E71: Hệ thống tạo đơn hàng thành công | F71: Hệ thống tạo đơn hàng thành công | G71: Passed | H71: 45983 | I71: Đức | J71: Passed | K71: 45987 | L71: Đức
A72: FUNC-GH14 | B72: Đặt hàng khi thiếu thông tin | C72: 1. Bỏ trống 1 trường bắt buộc (ví dụ số điện thoại) 2. Click “Đặt hàng” | D72: Có ít nhất 1 món trong giỏ | E72: Hệ thống hiển thị cảnh báo | F72: Hệ thống hiển thị cảnh báo | G72: Passed | H72: 45983 | I72: Đức | J72: Passed | K72: 45987 | L72: Đức

Sheet Đặt bàn
A1: Project Name | B1: CoffeeGo-Nền tảng đặt bàn quán cà phê tích hợp AI Assistant và thanh toán điện tử
A2: Module Code | B2: Đặt bàn
B3: Hoàn thành | C3: Lỗi | D3: Chưa kiểm tra | E3: Bị chặn | F3: Tổng lần kiểm tra
A4: Round 1 | B4: =COUNTA(A28:A59)- 1 -> 31 | C4: =COUNTIF(G:G,"Failed") -> 4 | D4: =COUNTIF(G:G,"Untested") -> 0 | E4: =COUNTIF(G:G,"Blocked") -> 0 | F4: =B4 -> 31
A5: Round 2 | B5: =COUNTA(A36:A59) -> 24 | C5: =COUNTIF(J:J,"Failed") -> 0 | D5: =COUNTIF(J:J,"Untested") -> 0 | E5: =COUNTIF(J:J,"Blocked") -> 0 | F5: =B5 -> 24
A24: Test Case ID | B24: Mô tả | C24: Quy trình | D24: Điều kiện tiên quyết | E24: Kết quả mong đợi | F24: Kết quả thực tế | G24: Kết quả | M24: Chú thích
G25: Vòng 1 | J25: Vòng 2
G26: Trạng thái | H26: Ngày kiểm tra | I26: Người kiểm tra | J26: Trạng thái | K26: Ngày kiểm tra | L26: Người kiểm tra
A27: GUI_SHOW Đặt bàn
A28: GUI-DB01 | B28: [Đặt bàn] Label | C28: - Truy cập vào trang "Đặt bàn" | D28: - Đã đăng nhập vào hệ thống | E28: -Text: Black -Trạng thái Enable | F28: -Text: Black -Trạng thái Enable | G28: Passed | H28: 45983 | I28: Khánh
A29: GUI-DB02 | B29: [Ngày] ComboBox | C29: - Truy cập vào trang "Đặt bàn" | D29: - Đã đăng nhập vào hệ thống | E29: -Text: Black -Trạng thái Enable | F29: -Text: Black -Trạng thái Enable | G29: Passed | H29: 45983 | I29: Khánh
A30: GUI-DB03 | B30: [Giờ] ComboBox | C30: - Truy cập vào trang "Đặt bàn" | D30: - Đã đăng nhập vào hệ thống | E30: - Text: Black - Trạng thái Enable | F30: - Text: Black - Trạng thái Enable | G30: Passed | H30: 45983 | I30: Khánh
A31: GUI-DB04 | B31: [Số điện thoại] Textbox | C31: - Truy cập vào trang "Đặt bàn" | D31: - Đã đăng nhập vào hệ thống | E31: - Text: Black - Border: none - Background-color: white - Trạng thái Enable | F31: - Text: Black - Border: none - Background-color: white - Trạng thái Enable | G31: Passed | H31: 45983 | I31: Khánh
A32: GUI-DB05 | B32: [Số lượng khách] Textbox | C32: - Truy cập vào trang "Đặt bàn" | D32: - Đã đăng nhập vào hệ thống | E32: - Text: Black - Border: none - Background-color: white - Trạng thái Enable | F32: - Text: Black - Border: none - Background-color: white - Trạng thái Enable | G32: Passed | H32: 45983 | I32: Khánh
A33: GUI-DB06 | B33: [Ghi chú] Textbox | C33: - Truy cập vào trang "Đặt bàn" | D33: - Đã đăng nhập vào hệ thống | E33: - Text: Black - Border: none - Background-color: white - Trạng thái Enable | F33: - Text: Black - Border: none - Background-color: white - Trạng thái Enable | G33: Passed | H33: 45983 | I33: Khánh
A34: GUI-DB07 | B34: [Đặt bàn] Button | C34: - Truy cập vào trang "Đặt bàn" | D34: - Đã đăng nhập vào hệ thống | E34: -Text: Black - Background-color: Grey - Border: none -Trạng thái Enable | F34: -Text: Black - Background-color: Grey - Border: none -Trạng thái Enable | G34: Passed | H34: 45983 | I34: Khánh
A35: FUNCTION_SHOW Đặt bàn
A36: FUNC-DB01 | B36: Nhập ngày hợp lệ | C36: - Trong trang "Đặt bàn" | D36: -Đã đăng nhập vào hệ thống | E36: Hệ thống chấp nhận và không báo gì | F36: Hệ thống chấp nhận và không báo gì | G36: Passed | H36: 45983 | I36: Khánh | J36: Passed | K36: 45987 | L36: Khánh
A37: FUNC-DB02 | B37: Không chọn ngày | C37: - Trong trang "Đặt bàn" | D37: -Đã đăng nhập vào hệ thống | E37: Hệ thống báo lỗi "Vui lòng chọn ngày" | F37: Hệ thống báo lỗi "Vui lòng chọn ngày" | G37: Passed | H37: 45983 | I37: Khánh | J37: Passed | K37: 45987 | L37: Khánh
A38: FUNC-DB03 | B38: Chọn ngày trong quá khứ | C38: - Trong trang "Đặt bàn" | D38: -Đã đăng nhập vào hệ thống | E38: Hệ thống báo lỗi "Ngày không hợp lệ" | F38: Hệ thống báo lỗi "Ngày không hợp lệ" | G38: Passed | H38: 45983 | I38: Khánh | J38: Passed | K38: 45987 | L38: Khánh
A39: FUNC-DB04 | B39: Chọn ngày hôm nay nhưng thời gian đã qua | C39: - Trong trang "Đặt bàn" | D39: -Đã đăng nhập vào hệ thống | E39: Hệ thống báo lỗi "Vui lòng chọn giờ hợp lệ" | F39: Hệ thống vẫn chấp nhận | G39: Failed | H39: 45983 | I39: Khánh | J39: Passed | K39: 45987 | L39: Khánh
A40: FUNC-DB05 | B40: Chọn giờ hợp lệ | C40: - Trong trang "Đặt bàn" | D40: -Đã đăng nhập vào hệ thống | E40: Hệ thống chấp nhận và không báo gì | F40: Hệ thống chấp nhận và không báo gì | G40: Passed | H40: 45983 | I40: Khánh | J40: Passed | K40: 45987 | L40: Khánh
A41: FUNC-DB06 | B41: không chọn giờ | C41: - Trong trang "Đặt bàn" | D41: -Đã đăng nhập vào hệ thống | E41: Hệ thống báo lỗi "Vui lòng chọn giờ" | F41: Hệ thống báo lỗi "Vui lòng chọn giờ" | G41: Passed | H41: 45983 | I41: Khánh | J41: Passed | K41: 45987 | L41: Khánh
A42: FUNC-DB07 | B42: Chọn giờ ngoài khung giờ hoạt động | C42: - Trong trang "Đặt bàn" | D42: -Đã đăng nhập vào hệ thống | E42: Hệ thống báo lỗi "Giờ không hợp lệ" | F42: Hệ thống vẫn chấp nhận | G42: Failed | H42: 45983 | I42: Khánh | J42: Passed | K42: 45987 | L42: Khánh
A43: FUNC-DB08 | B43: Nhập đúng định dạng số điện thoại | C43: - Trong trang "Đặt bàn" | D43: -Đã đăng nhập vào hệ thống | E43: Hệ thống chấp nhận và không báo gì | F43: Hệ thống chấp nhận và không báo gì | G43: Passed | H43: 45983 | I43: Khánh | J43: Passed | K43: 45987 | L43: Khánh
A44: FUNC-DB09 | B44: Không nhập số điện thoại | C44: - Trong trang "Đặt bàn" | D44: -Đã đăng nhập vào hệ thống | E44: Hệ thống hiển thị thống báo "Vui lòng nhập số điện thoại" | F44: Hệ thống hiển thị thống báo "Vui lòng nhập số điện thoại" | G44: Passed | H44: 45983 | I44: Khánh | J44: Passed | K44: 45987 | L44: Khánh
A45: FUNC-DB10 | B45: Nhập ít hơn 10 số | C45: - Trong trang "Đặt bàn" | D45: -Đã đăng nhập vào hệ thống | E45: Hệ thống thông báo "Số điện thoại không hợp lệ" | F45: Hệ thống thông báo "Số điện thoại không hợp lệ" | G45: Passed | H45: 45983 | I45: Khánh | J45: Passed | K45: 45987 | L45: Khánh
A46: FUNC-DB11 | B46: Nhập nhiều hơn 10 số | C46: - Trong trang "Đặt bàn" | D46: -Đã đăng nhập vào hệ thống | E46: Hệ thống thông báo "Số điện thoại không hợp lệ" | F46: Hệ thống thông báo "Số điện thoại không hợp lệ" | G46: Passed | H46: 45983 | I46: Khánh | J46: Passed | K46: 45987 | L46: Khánh
A47: FUNC-DB12 | B47: Nhập số điện thoại có chứa chữ | C47: - Trong trang "Đặt bàn" | D47: -Đã đăng nhập vào hệ thống | E47: Hệ thống thông báo "Số điện thoại không hợp lệ" | F47: Hệ thống thông báo "Số điện thoại không hợp lệ" | G47: Passed | H47: 45983 | I47: Khánh | J47: Passed | K47: 45987 | L47: Khánh
... A59: FUNC-DB24 | B59: Nhấn chọn bàn khi đã điền tất cả các mục mà không điền số lượng khách | C59: - Trong trang "Đặt bàn" | D59: -Đã đăng nhập vào hệ thống | E59: Hệ thống báo lỗi "Yêu cầu nhập số lượng khách" | F59: Hệ thống báo lỗi "Yêu cầu nhập số lượng khách" | G59: Passed | H59: 45983 | I59: Khánh | J59: Passed | K59: 45987 | L59: Khánh

Sheet Order
A1: Project Name | B1: CoffeeGo-Nền tảng đặt bàn quán cà phê tích hợp AI Assistant và thanh toán điện tử
A2: Module Code | B2: Order
B3: Hoàn thành | C3: Lỗi | D3: Chưa kiểm tra | E3: Bị chặn | F3: Tổng lần kiểm tra
A4: Round 1 | B4: =COUNTA(A35:A58)- 1 -> 23 | C4: =COUNTIF(G:G,"Failed") -> 3 | D4: =COUNTIF(G:G,"Untested") -> 0 | E4: =COUNTIF(G:G,"Blocked") -> 0 | F4: =B4 -> 23
A5: Round 2 | B5: =COUNTA(A53:A71) -> 6 | C5: =COUNTIF(J:J,"Failed") -> 0 | D5: =COUNTIF(J:J,"Untested") -> 0 | E5: =COUNTIF(J:J,"Blocked") -> 0 | F5: =B5 -> 6
A31: Test Case ID | B31: Mô tả | C31: Quy trình | D31: Điều kiện tiên quyết | E31: Kết quả mong đợi | F31: Kết quả thực tế | G31: Kết quả | M31: Chú thích
G32: Vòng 1 | J32: Vòng 2
G33: Trạng thái | H33: Ngày kiểm tra | I33: Người kiểm tra | J33: Trạng thái | K33: Ngày kiểm tra | L33: Người kiểm tra
A34: GUI_SHOW Order
A35: GUI-OD01 | B35: [Quản lý Menu] Heading | E35: -Text: Black -Status: Enable | F35: -Text: Black -Status: Enable | G35: Passed | H35: 45983 | I35: Huy
A36: GUI-OD02 | B36: [Danh sách món] Image | E36: -Status: Visible -Image: Clear | F36: -Status: Visible -Image: Clear | G36: Passed | H36: 45983 | I36: Huy
A37: GUI-OD03 | B37: [Tên món] Label | E37: -Text: Black -Status: Enable | F37: -Text: Black -Status: Enable | G37: Passed | H37: 45983 | I37: Huy
A38: GUI-OD04 | B38: [Giá món] Label | E38: -Text: Red -Status: Enable | F38: -Text: Red -Status: Enable | G38: Passed | H38: 45983 | I38: Huy
A39: GUI-OD05 | B39: [Danh sách món] Card | E39: -Background-color: White -Status: Enable | F39: -Background-color: White -Status: Enable | G39: Passed | H39: 45983 | I39: Huy
A40: GUI-OD06 | B40: [Bàn] Heading | E40: -Text: Black -Status: Enable | F40: -Text: Black -Status: Enable | G40: Passed | H40: 45983 | I40: Huy
A41: GUI-OD07 | B41: [Danh sách order] Table | E41: -Text: Black -Status: Enable | F41: -Text: Black -Status: Enable | G41: Passed | H41: 45983 | I41: Huy
A42: GUI-OD08 | B42: [Tăng/giảm]Button | E42: -Background-color: Green/red -Status: Enable | F42: -Background-color: Green/red -Status: Enable | G42: Passed | H42: 45983 | I42: Huy
A43: GUI-OD09 | B43: [Xóa]Button | E43: -Background-color: Red -Status: Enable | F43: -Background-color: Red -Status: Enable | G43: Passed | H43: 45983 | I43: Huy
A44: GUI-OD10 | B44: [Tổng tiền] Label | E44: -Text: Black -Status: Enable | F44: -Text: Black -Status: Enable | G44: Passed | H44: 45983 | I44: Huy
A45: GUI-OD11 | B45: [Xác nhận] Button | E45: -Text color: White -Background-color: Green -Status: Enable | F45: -Text color: White -Background-color: Green -Status: Enable | G45: Passed | H45: 45983 | I45: Huy
A46: GUI-OD12 | B46: [Hủy] Button | E46: -Text color: White -Background-color: Red -Status: Enable | F46: -Text color: White -Background-color: Red -Status: Enable | G46: Passed | H46: 45983 | I46: Huy
A47: FUNCTION_SHOW Order
A48: FUNC-OD01 | B48: Hiển thị danh sách menu | C48: 1. Truy cập vào menu "Order". | D48: Đăng nhập nhân viên thành công vào hệ thống | E48: Hiển thị đầy đủ thông tin món"Hình ảnh","Tên món", "Giá tiền". | F48: Hiển thị đầy đủ thông tin món"Hình ảnh","Tên món", "Giá tiền". | G48: Passed | H48: 45983 | I48: Huy | J48: Passed | K48: 45987 | L48: Huy
A49: FUNC-OD02 | B49: Thêm món vào danh sách order | C49: 1.Click vào 1 món bất kỳ | D49: Có ít nhất 1 món trong menu | E49: Món được thêm vào danh sách order | F49: Món được thêm vào danh sách order | G49: Passed | H49: 45983 | I49: Huy | J49: Passed | K49: 45987 | L49: Huy
A50: FUNC-OD03 | B50: Tăng/giảm số lượng món | C50: 1.Click nút tăng/giảm trên hóa đơn | D50: Món đã thêm trong đơn | E50: Số lượng món tăng/giảm 1 | F50: Số lượng món tăng/giảm 1 | G50: Passed | H50: 45983 | I50: Huy | J50: Passed | K50: 45987 | L50: Huy
A51: FUNC-OD04 | B51: Tính tiền theo số lượng | C51: 1.Thêm cùng món nhiều lần | D51: Món đã thêm trong đơn | E51: Tổng tiền hiển thị chính xác số lượng món có trong đơn | F51: Tổng tiền hiển thị chính xác số lượng món có trong đơn | G51: Passed | H51: 45983 | I51: Huy | J51: Passed | K51: 45987 | L51: Huy
A52: FUNC-OD05 | B52: Tính tổng tiền | C52: 1.Thêm nhiều món khác nhau | D52: Có ít nhất 1 món trong đơn | E52: Tổng tiền hiển thị chính xác số lượng món có trong đơn | F52: Tổng tiền hiển thị chính xác số lượng món có trong đơn | G52: Passed | H52: 45983 | I52: Huy | J52: Passed | K52: 45987 | L52: Huy
A53: FUNC-OD06 | B53: Click Xác nhận order | C53: 1.Click button “Xác nhận” | D53: Có ít nhất 1 món trong đơn | E53: Hiển thị form thông tin đơn và thanh toán | F53: Hiển thị form thông tin đơn và thanh toán | G53: Passed | H53: 45983 | I53: Huy | J53: Passed | K53: 45987 | L53: Huy
A54: FUNC-OD07 | B54: Click Hủy order khi đã thêm món | C54: 1.Thêm món bất kì 2.Click nút Hủy | D54: Đã có ít nhất 1 món trong danh sách order | E54: Hiển thị thông báo"Bạn có chắc muốn hủy?" | F54: Hiển thị thông báo"Bạn có chắc muốn hủy?" | G54: Passed | H54: 45983 | I54: Huy | J54: Passed | K54: 45987 | L54: Huy
A55: FUNC-OD08 | B55: Xác nhận thất bại khi chưa có món | C55: 1.Click “Xác nhận” khi order trống | D55: Không có món trong đơn | E55: Hiển thị thống báo:"Chưa có món" | F55: Không hiển thị thông báo thất bại khi bấm xác nhận trong trang order | G55: Failed | H55: 45983 | I55: Huy | J55: Passed | K55: 45987 | L55: Huy
A56: FUNC-OD09 | B56: Xóa món | C56: 1.Click nút “Xóa” khi có món trong danh sách món | D56: Có ít nhất 1 món trong danh sách order | E56: Món được xóa khỏi danh sách order | F56: Món được xóa khỏi danh sách order | G56: Passed | H56: 45983 | I56: Huy | J56: Passed | K56: 45987 | L56: Huy
A57: FUNC-OD10 | B57: Tìm món theo từ khóa | C57: 1.Nhập 1 từ bất kỳ vào tìm kiếm | D57: Món tìm kiếm tồn tại | E57: Hiển thị danh sách các món phù hợp với từ khóa | F57: Danh sách món không tự động cập nhật theo danh mục | G57: Failed | H57: 45983 | I57: Huy | J57: Passed | K57: 45987 | L57: Huy
A58: FUNC-OD11 | B58: Chọn danh mục món | C58: 1.Nhấn dropdown hiển thị các danh mục món 2.Chọn danh mục món | D58: Danh mục tồn tại | E58: Hiển thị danh sách món theo danh mục món đã chọn | F58: Danh sách món không tự động cập nhật theo từ khóa | G58: Failed | H58: 45983 | I58: Huy | J58: Passed | K58: 45987 | L58: Huy

Sheet Lịch sử đặt hàng
A1: Project Name | B1: CoffeeGo-Nền tảng đặt bàn quán cà phê tích hợp AI Assistant và thanh toán điện tử
A2: Module Code | B2: Lịch sử đặt hàng
B3: Hoàn thành | C3: Lỗi | D3: Chưa kiểm tra | E3: Bị chặn | F3: Tổng lần kiểm tra
A4: Round 1 | B4: =COUNTA(A35:A54)- 1 -> 19 | C4: =COUNTIF(G:G,"Failed") -> 0 | D4: =COUNTIF(G:G,"Untested") -> 0 | E4: =COUNTIF(G:G,"Blocked") -> 0 | F4: =B4 -> 19
A5: Round 2 | B5: =COUNTA(A47:A54) -> 8 | C5: =COUNTIF(J:J,"Failed") -> 0 | D5: =COUNTIF(J:J,"Untested") -> 0 | E5: =COUNTIF(J:J,"Blocked") -> 0 | F5: =B5 -> 8
A31: Test Case ID | B31: Mô tả | C31: Quy trình | D31: Điều kiện tiên quyết | E31: Kết quả mong đợi | F31: Kết quả thực tế | G31: Kết quả | M31: Chú thích
G32: Vòng 1 | J32: Vòng 2
G33: Trạng thái | H33: Ngày kiểm tra | I33: Người kiểm tra | J33: Trạng thái | K33: Ngày kiểm tra | L33: Người kiểm tra
A34: GUI_SHOW Lịch sử đặt hàng
A35: GUI - LSDH01 | B35: [Sidebar Menu] Active State | C35: 1. Đăng nhập tài khoản khách hàng 2. Chọn menu "Lịch sử mua hàng" | D35: Tài khoản đã kích hoạt | E35: - Mục "Lịch sử đơn hàng" ở menu bên trái | F35: - Mục "Lịch sử đơn hàng" ở menu bên trái | G35: Passed | H35: 45983 | I35: Tấn | J35: Passed
A36: GUI - LSDH02 | B36: [Lịch sử đặt hàng] Label | D36: Tài khoản đã kích hoạt | E36: - Label: Gray - Status: Enable | F36: - Label: Gray - Status: Enable | G36: Passed | H36: 45983 | I36: Tấn | J36: Passed
A37: GUI - LSDH03 | B37: [Đơn hàng] Label | D37: Tài khoản đã kích hoạt | E37: - Label: Gray - Status: Enable | F37: - Label: Gray - Status: Enable | G37: Passed | H37: 45983 | I37: Tấn | J37: Passed
A38: GUI - LSDH04 | B38: [Tên Khách Hàng] Label | D38: Tài khoản đã kích hoạt | E38: - Label: Gray - Status: Enable | F38: - Label: Gray - Status: Enable | G38: Passed | H38: 45983 | I38: Tấn | J38: Passed
A39: GUI - LSDH05 | B39: [Ngày] Label | D39: Tài khoản đã kích hoạt | E39: - Label: Gray - Status: Enable | F39: - Label: Gray - Status: Enable | G39: Passed | H39: 45983 | I39: Tấn | J39: Passed
A40: GUI - LSDH06 | B40: [Sản Phẩm] Label | D40: Tài khoản đã kích hoạt | E40: - Label: Gray - Status: Enable | F40: - Label: Gray - Status: Enable | G40: Passed | H40: 45983 | I40: Tấn | J40: Passed
A41: GUI - LSDH07 | B41: [Thông tin giao hàng] Label | D41: Tài khoản đã kích hoạt | E41: - Label: Gray - Status: Enable | F41: - Label: Gray - Status: Enable | G41: Passed | H41: 45983 | I41: Tấn | J41: Passed
A42: GUI - LSDH08 | B42: [Thông tin thanh toán] Label | D42: Tài khoản đã kích hoạt | E42: - Label: Gray - Status: Enable | F42: - Label: Gray - Status: Enable | G42: Passed | H42: 45983 | I42: Tấn | J42: Passed
A43: GUI - LSDH09 | B43: [Giá trị] Label | D43: Tài khoản đã kích hoạt | E43: - Label: Gray - Status: Enable | F43: - Label: Gray - Status: Enable | G43: Passed | H43: 45983 | I43: Tấn | J43: Passed
A44: GUI - LSDH10 | B44: [Trạng thái] Label | D44: Tài khoản đã kích hoạt | E44: - Label: Gray - Status: Enable | F44: - Label: Gray - Status: Enable | G44: Passed | H44: 45983 | I44: Tấn | J44: Passed
A45: GUI - LSDH11 | B45: [Thao tác] Label | D45: Tài khoản đã kích hoạt | E45: - Label: Gray - Status: Enable | F45: - Label: Gray - Status: Enable | G45: Passed | H45: 45983 | I45: Tấn | J45: Passed
A46: FUNCTION_SHOW Lịch sử đặt hàng
A47: FUNC-LSDH01 | B47: Hiển thị danh sách đơn hàng đã đặt | C47: 1. Đăng nhập tài khoản khách hàng. 2. Vào mục "Lịch sử mua hàng". | D47: Đang ở trang lịch sử đặt hàng | E47: Hệ thống hiển thị danh sách các đơn hàng cũ, sắp xếp theo ngày gần nhất lên đầu. | F47: Danh sách hiển thị đúng thứ tự thời gian. | G47: Passed | H47: 45983 | I47: Tấn | J47: Passed | K47: 45987 | L47: Tấn
A48: FUNC-LSDH02 | B48: Kiểm tra dữ liệu cột "Sản phẩm" | C48: 1. Quan sát cột Sản phẩm của đơn hàng gần nhất. 2. So sánh với lúc đặt hàng. | D48: Đang ở trang lịch sử đặt hàng | E48: Hiển thị đầy đủ tên các món ăn và số lượng tương ứng trong đơn. | F48: Hiển thị đúng tên món và số lượng. | G48: Passed | H48: 45983 | I48: Tấn | J48: Passed | K48: 45987 | L48: Tấn
A49: FUNC-LSDH03 | B49: Kiểm tra dữ liệu cột "Thông tin giao hàng" | C49: 1. Quan sát cột TT Giao hàng. 2. Kiểm tra SĐT và Địa chỉ. | D49: Đang ở trang lịch sử đặt hàng | E49: Hiển thị chính xác thông tin người nhận tại thời điểm đặt đơn. | F49: Hiển thị chính xác thông tin người nhận tại thời điểm đặt đơn. | G49: Passed | H49: 45983 | I49: Tấn | J49: Passed | K49: 45987 | L49: Tấn
A50: FUNC-LSDH04 | B50: Click icon "Mắt" xem chi tiết đơn hàng | C50: 1. Tại dòng đơn hàng bất kỳ. 2. Click vào icon Con mắt ở cột Thao tác. | D50: Đang ở trang lịch sử đặt hàng | E50: Hệ thống mở Popup chi tiết đơn hàng | F50: Popup hiển thị chi tiết đơn hàng thành công. | G50: Passed | H50: 45983 | I50: Tấn | J50: Passed | K50: 45987 | L50: Tấn
A51: FUNC-LSDH05 | B51: Hiển thị trạng thái "Đang xử lý" | C51: 1. Đặt một đơn hàng mới. 2. Vào lịch sử mua hàng kiểm tra ngay. | D51: Đang ở trang lịch sử đặt hàng | E51: Trạng thái hiển thị là "Đang xử lý" | F51: Trạng thái hiển thị là "Đang xử lý" | G51: Passed | H51: 45983 | I51: Tấn | J51: Passed | K51: 45987 | L51: Tấn
A52: FUNC-LSDH06 | B52: Hiển thị trạng thái "Đã xử lý" | C52: 1. Đợi Admin duyệt và hoàn thành đơn. | D52: Đang ở trang lịch sử đặt hàng | E52: Trạng thái chuyển sang "Đã xử lý" | F52: Trạng thái chuyển sang "Đã xử lý" | G52: Passed | H52: 45983 | I52: Tấn | J52: Passed | K52: 45987 | L52: Tấn
A53: FUNC-LSDH07 | B53: Kiểm tra phân trang (Pagination) | C53: 1. Tài khoản có trên 10 hoặc 20 đơn hàng (vượt quá giới hạn 1 trang). 2. Kéo xuống dưới cùng. | D53: Đang ở trang lịch sử đặt hàng | E53: Hiển thị thanh phân trang (1, 2, 3, Next). Click chuyển trang hoạt động tốt. | F53: Phân trang hoạt động bình thường. | G53: Passed | H53: 45983 | I53: Tấn | J53: Passed | K53: 45987 | L53: Tấn
A54: FUNC-LSDH08 | B54: Kiểm tra hiển thị khi chưa có đơn hàng nào | C54: 1. Tạo tài khoản mới tinh. 2. Vào "Lịch sử mua hàng". | D54: Đang ở trang lịch sử đặt hàng | E54: Hiển thị thông báo "Bạn chưa có đơn hàng nào" | F54: Hiển thị thông báo "Bạn chưa có đơn hàng nào" | G54: Passed | H54: 45983 | I54: Tấn | J54: Passed | K54: 45987 | L54: Tấn

Sheet Quản lý đặt bàn
A1: Project Name | B1: CoffeeGo-Nền tảng đặt bàn quán cà phê tích hợp AI Assistant và thanh toán điện tử
A2: Module Code | B2: Quản lý đặt bàn
B3: Hoàn thành | C3: Lỗi | D3: Chưa kiểm tra | E3: Bị chặn | F3: Tổng lần kiểm tra
A4: Round 1 | B4: 15 | C4: =COUNTIF(G:G,"Failed") -> 1 | D4: =COUNTIF(G:G,"Untested") -> 0 | E4: =COUNTIF(G:G,"Blocked") -> 0 | F4: =B4 -> 15
A5: Round 2 | B5: =COUNTA(A42:A46) -> 5 | C5: =COUNTIF(J:J,"Failed") -> 0 | D5: =COUNTIF(J:J,"Untested") -> 0 | E5: =COUNTIF(J:J,"Blocked") -> 0 | F5: =B5 -> 5
A26: Test Case ID | B26: Mô tả | C26: Quy trình | D26: Điều kiện tiên quyết | E26: Kết quả mong đợi | F26: Kết quả thực tế | G26: Kết quả | M26: Chú thích
G27: Vòng 1 | J27: Vòng 2
G28: Trạng thái | H28: Ngày kiểm tra | I28: Người kiểm tra | J28: Trạng thái | K28: Ngày kiểm tra | L28: Người kiểm tra
A29: GUI_SHOW Quản lý đặt bàn
A30: GUI - QLDB01 | B30: [Quản lý đặt bàn] Label | D30: Đăng nhập với vai trò Admin thành công. | E30: - Label: Gray - Status: Enable - Background: Highlight | F30: - Label: Gray - Status: Enable - Background: Highlight | G30: Passed | H30: 45984 | I30: Tấn | J30: Passed
A31: GUI - QLDB02 | B31: [QUẢN LÝ ĐẶT BÀN] Label | D31: Đăng nhập với vai trò Admin thành công. | E31: - Label: Black - Status: Enable - Font-weight: Bold | F31: - Label: Black - Status: Enable - Font-weight: Bold | G31: Passed | H31: 45984 | I31: Tấn | J31: Passed
A32: GUI - QLDB03 | B32: [STT] Label | D32: Đăng nhập với vai trò Admin thành công. | E32: - Label: Gray - Status: Enable | F32: - Label: Gray - Status: Enable | G32: Passed | H32: 45984 | I32: Tấn | J32: Passed
A33: GUI - QLDB04 | B33: [Tên khách] Label | D33: Đăng nhập với vai trò Admin thành công. | E33: - Label: Gray - Status: Enable | F33: - Label: Gray - Status: Enable | G33: Passed | H33: 45984 | I33: Tấn | J33: Passed
A34: GUI - QLDB05 | B34: [Số điện thoại] Label | D34: Đăng nhập với vai trò Admin thành công. | E34: - Label: Gray - Status: Enable | F34: - Label: Gray - Status: Enable | G34: Passed | H34: 45984 | I34: Tấn | J34: Passed
A35: GUI - QLDB06 | B35: [Ngày đặt] Label | D35: Đăng nhập với vai trò Admin thành công. | E35: - Label: Gray - Status: Enable | F35: - Label: Gray - Status: Enable | G35: Passed | H35: 45984 | I35: Tấn | J35: Passed
A36: GUI - QLDB07 | B36: [Giờ đặt] Label | D36: Đăng nhập với vai trò Admin thành công. | E36: - Label: Gray - Status: Enable | F36: - Label: Gray - Status: Enable | G36: Passed | H36: 45984 | I36: Tấn | J36: Passed
A37: GUI - QLDB09 | B37: [Trạng thái] Label | D37: Đăng nhập với vai trò Admin thành công. | E37: - Label: Gray - Status: Enable | F37: - Label: Gray - Status: Enable | G37: Passed | H37: 45984 | I37: Tấn | J37: Passed
A38: GUI - QLDB10 | B38: [Hành động] Label | D38: Đăng nhập với vai trò Admin thành công. | E38: - Label: Gray - Status: Enable | F38: - Label: Gray - Status: Enable | G38: Passed | H38: 45984 | I38: Tấn | J38: Passed
A39: GUI - QLDB11 | B39: [Xác nhận] Button | D39: Đăng nhập với vai trò Admin thành công. | E39: - background color: gray - Status: Enable | F39: - background color: gray - Status: Enable | G39: Passed | H39: 45984 | I39: Tấn | J39: Passed
A40: GUI - QLDB12 | B40: [Hủy] Button | D40: Đăng nhập với vai trò Admin thành công. | E40: - background color: red - Status: Enable | F40: - background color: red - Status: Enable | G40: Passed | H40: 45984 | I40: Tấn | J40: Passed
A41: FUNCTION_SHOW Quản lý đặt bàn
A42: FUNC-QLDB01 | B42: Hiển thị danh sách đặt bàn | C42: 1. Truy cập vào menu "Quản lý đặt bàn". | D42: Đăng nhập với vai trò Admin thành công. | E42: Danh sách hiển thị đầy đủ các cột: STT, Tên, SĐT, Ngày, Giờ, Mã bàn, Trạng thái, Hành động. | F42: Danh sách hiển thị đầy đủ các cột: STT, Tên, SĐT, Ngày, Giờ, Mã bàn, Trạng thái, Hành động. | G42: Passed | H42: 45984 | I42: Tấn | J42: Passed | K42: 45987 | L42: Tấn
A43: FUNC-QLDB02 | B43: Xử lý xác nhận đặt bàn (Click nút xác nhận) | C43: 1. Tìm đơn có trạng thái "Chờ xử lý". 2. Nhấn vào [Xác nhận] Button. | D43: Đơn hàng chưa được xử lý. | E43: 1. Trạng thái đơn đổi thành "Đã xác nhận". 2. Hai nút [Xác nhận] và [Hủy] biến mất khỏi dòng đó. | F43: 1. Trạng thái đơn đổi thành "Đã xác nhận". 2. Hai nút [Xác nhận] và [Hủy] biến mất khỏi dòng đó. | G43: Failed | H43: 45984 | I43: Tấn | J43: Passed | K43: 45987 | L43: Tấn
A44: FUNC-QLDB03 | B44: Xử lý hủy đơn (Click nút X) | C44: 1. Tìm đơn có trạng thái "Chờ xử lý". 2. Nhấn vào [Hủy] Button. | D44: Đơn hàng chưa được xử lý. | E44: 1. Hiển thị thông báo xác nhận. 2. Trạng thái đơn đổi thành "Đã hủy" | F44: 1. Hiển thị thông báo xác nhận. 2. Trạng thái đơn đổi thành "Đã hủy" | G44: Passed | H44: 45984 | I44: Tấn | J44: Passed | K44: 45987 | L44: Tấn
A45: FUNC-QLDB04 | B45: Kiểm tra hiển thị bàn "Đã xác nhận" | C45: 1. Quan sát đơn đã được duyệt từ trước | D45: Đơn đã xử lý xong. | E45: Cột "Hành động" phải để trống để tránh thao tác trùng lặp. | F45: Cột "Hành động" phải để trống để tránh thao tác trùng lặp. | G45: Passed | H45: 45984 | I45: Tấn | J45: Passed | K45: 45987 | L45: Tấn
A46: FUNC-QLDB05 | B46: Kiểm tra sắp xếp thời gian (Sort) | C46: 1. Quan sát cột "Ngày đặt". 2. So sánh thứ tự các dòng. | D46: Dữ liệu hiển thị. | E46: Các đơn đặt bàn cho ngày gần nhất nên được sắp xếp lên đầu | F46: Các đơn đặt bàn cho ngày gần nhất nên được sắp xếp lên đầu | G46: Passed | H46: 45984 | I46: Tấn | J46: Passed | K46: 45987 | L46: Tấn

Sheet Danh sách khuyến mãi
A1: Project Name | B1: CoffeeGo-Nền tảng đặt bàn quán cà phê tích hợp AI Assistant và thanh toán điện tử
A2: Module Code | B2: Danh sách khuyến mãi
B3: Hoàn thành | C3: Lỗi | D3: Chưa kiểm tra | E3: Bị chặn | F3: Tổng lần kiểm tra
A4: Round 1 | B4: =COUNTA(A31:A44)- 1 -> 13 | C4: =COUNTIF(G:G,"Failed") -> 2 | D4: =COUNTIF(G:G,"Untested") -> 0 | E4: =COUNTIF(G:G,"Blocked") -> 0 | F4: =B4 -> 13
A5: Round 2 | B5: =COUNTA(A39:A44) -> 6 | C5: =COUNTIF(J:J,"Failed") -> 1 | D5: =COUNTIF(J:J,"Untested") -> 0 | E5: =COUNTIF(J:J,"Blocked") -> 0 | F5: =B5 -> 6
A27: Test Case ID | B27: Mô tả | C27: Quy trình | D27: Điều kiện tiên quyết | E27: Kết quả mong đợi | F27: Kết quả thực tế | G27: Kết quả | M27: Chú thích
G28: Vòng 1 | J28: Vòng 2
G29: Trạng thái | H29: Ngày kiểm tra | I29: Người kiểm tra | J29: Trạng thái | K29: Ngày kiểm tra | L29: Người kiểm tra
A30: GUI_SHOW Danh sách khuyến mãi
A31: GUI-DSKM01 | B31: [Quản lý voucher] Label | E31: -Label : black -Status : enable | F31: -Label : black -Status : enable | G31: Passed | H31: 45984 | I31: Huy | J31: Passed
A32: GUI-DSKM02 | B32: [Tìm kiếm] Textbox | E32: -Label : black -Status : enable | F32: -Label : black -Status : enable | G32: Passed | H32: 45984 | I32: Huy | J32: Passed
A33: GUI-DSKM03 | B33: [Thêm voucher] Button | E33: -Label : white -Status : enable -Background:Green | F33: -Label : white -Status : enable -Background:Green | G33: Passed | H33: 45984 | I33: Huy | J33: Passed
A34: GUI-DSKM04 | B34: [Danh sách khuyến mãi] Table | E34: - Text: Black - Status: Enable | F34: - Text: Black - Status: Enable | G34: Passed | H34: 45984 | I34: Huy | J34: Passed
A35: GUI-DSKM05 | B35: [Tình trạng] Button | E35: -Label : white -Status : enable -Background:Blue,Green,Brown | F35: -Label : white -Status : enable -Background:Blue,Green,Brown | G35: Passed | H35: 45984 | I35: Huy | J35: Passed
A36: GUI-DSKM06 | B36: [Chỉnh sửa] Button | E36: -Status : enable -Color:Blue | F36: -Status : enable -Color:Blue | G36: Passed | H36: 45984 | I36: Huy | J36: Passed
A37: GUI-DSKM07 | B37: [Khóa] Button | E37: -Status : enable -Color:Red | F37: -Status : enable -Color:Red | G37: Passed | H37: 45984 | I37: Huy | J37: Passed
A38: FUNCTION_SHOW Danh sách khuyến mãi
A39: FUNC-DSKM01 | B39: Hiển thị danh sách voucher | C39: 1. Truy cập vào trang web 2. Click: "Tài khoản" 3. Click: "Quản lý" 4. Click: "Quản lý khuyến mãi" | D39: Đăng nhập thành công vào hệ thống | E39: Hệ thống hiển thị đúng thông tin đanh sách voucher | F39: Hệ thống hiển thị đúng thông tin đanh sách voucher | G39: Passed | H39: 45984 | I39: Huy | J39: Passed | K39: 45987 | L39: Huy
A40: FUNC-DSKM02 | B40: Tìm kiếm mã voucher | C40: 1. Truy cập vào trang web 2. Click: "Tài khoản" 3. Click: "Quản lý" 4. Click: "Quản lý voucher" 5. Click vào ô tìm kiếm 6. Nhập mã voucher | D40: Đăng nhập thành công vào hệ thống | E40: Hệ thống hiển thị mã cần tìm | F40: Hệ thống hiển thị mã cần tìm | G40: Passed | H40: 45984 | I40: Huy | J40: Passed | K40: 45987 | L40: Huy
A41: FUNC-DSKM03 | B41: Tìm kiếm từ có trong mã | C41: 1. Truy cập vào trang web 2. Click: "Tài khoản" 3. Click: "Quản lý" 4. Click: "Quản lý voucher" 5. Click vào ô tìm kiếm 6. Nhập 1 hoặc 2 ký tự | D41: Đăng nhập thành công vào hệ thống | E41: Hệ thống hiển thị mã có từ cần tìm | F41: Hệ thống hiển thị mã có từ cần tìm | G41: Passed | H41: 45984 | I41: Huy | J41: Passed | K41: 45987 | L41: Huy
A42: FUNC-DSKM04 | B42: Click vào nút "Cập nhật" để mở form chỉnh sửa khuyến mãi | C42: 1. Truy cập vào trang web 2.Chọn"Tài khoản" 3.Chọn"Quản lý" 3.Chọn "Quản lý voucher" 4.Click nút "Cập nhật" | D42: Đăng nhập admin thành công vào hệ thống | E42: Hệ thống mở được form chỉnh sửa mã khuyến mãi | F42: Hệ thống không mở được form chỉnh sửa mã khuyến mãi | G42: Failed | H42: 45984 | I42: Huy | J42: Failed | K42: 45987 | L42: Huy
A43: FUNC-DSKM05 | B43: Khóa mã khuyến mãi thành công khi chọn nút"khóa" | C43: 1. Truy cập vào trang web 2.Chọn"Tài khoản" 3.Chọn"Quản lý" 3.Chọn "Quản lý voucher" 4.Click nút "Khóa" | D43: Đăng nhập admin thành công vào hệ thống | E43: Hệ thống thông báo"Khóa khuyến mãi thành công" | F43: Hệ thống không thông báo"Khóa khuyến mãi thành công" | G43: Failed | H43: 45984 | I43: Huy | J43: Passed | K43: 45987 | L43: Huy
A44: FUNC-DSKM06 | B44: Hiển thị đúng mã khuyến mãi sau khi thêm mới khuyến mãi | C44: 1. Truy cập vào trang web 2.Chọn"Tài khoản" 3.Chọn"Quản lý" 3.Chọn "Quản lý voucher" 4.Click "Thêm mới voucher" 5.Điền thông tin voucher 6.Click"Thêm mới" | D44: Đăng nhập admin thành công vào hệ thống | E44: Hệ thống cập nhật và hiển thị đúng mã khuyến mãi vừa thêm | F44: Hệ thống cập nhật và hiển thị đúng mã khuyến mãi vừa thêm | G44: Passed | H44: 45984 | I44: Huy | J44: Passed | K44: 45987 | L44: Huy

Sheet Thêm khuyến mãi
A1: Project Name | B1: CoffeeGo-Nền tảng đặt bàn quán cà phê tích hợp AI Assistant và thanh toán điện tử
A2: Module Code | B2: Thêm khuyến mãi
B3: Hoàn thành | C3: Lỗi | D3: Chưa kiểm tra | E3: Bị chặn | F3: Tổng lần kiểm tra
A4: Round 1 | B4: =COUNTA(A35:A66)- 1 -> 31 | C4: =COUNTIF(G:G,"Failed") -> 1 | D4: =COUNTIF(G:G,"Untested") -> 0 | E4: =COUNTIF(G:G,"Blocked") -> 0 | F4: =B4 -> 31
A5: Round 2 | B5: =COUNTA(A52:A66) -> 15 | C5: =COUNTIF(J:J,"Failed") -> 0 | D5: =COUNTIF(J:J,"Untested") -> 0 | E5: =COUNTIF(J:J,"Blocked") -> 0 | F5: =B5 -> 15
A31: Test Case ID | B31: Mô tả | C31: Quy trình | D31: Điều kiện tiên quyết | E31: Kết quả mong đợi | F31: Kết quả thực tế | G31: Kết quả | M31: Chú thích
G32: Vòng 1 | J32: Vòng 2
G33: Trạng thái | H33: Ngày kiểm tra | I33: Người kiểm tra | J33: Trạng thái | K33: Ngày kiểm tra | L33: Người kiểm tra
A34: GUI_SHOW Thêm voucher mới
A35: GUI - TVM01 | B35: [Thêm voucher mới] heading | E35: - Text: White - Status: Enable -Background:Green | F35: - Text: White - Status: Enable -Background:Green | G35: Passed | H35: 45770 | I35: Huy
A36: GUI - TVM02 | B36: [Mã voucher] label | E36: - Text: Black - Status: Enable | F36: - Text: Black - Status: Enable | G36: Passed | H36: 45770 | I36: Huy
A37: GUI - TVM03 | B37: [Nhập mã voucher] Textbox | E37: - Text: Black - Status: Enable | F37: - Text: Black - Status: Enable | G37: Passed | H37: 45770 | I37: Huy
A38: GUI - TVM04 | B38: [Mô tả] label | E38: - Text: Black - Status: Enable | F38: - Text: Black - Status: Enable | G38: Passed | H38: 45770 | I38: Huy
A39: GUI - TVM05 | B39: [Nhập mô tả] textbox | E39: - Text: Black - Status: Enable | F39: - Text: Grey - Status: Enable | G39: Passed | H39: 45770 | I39: Huy
A40: GUI - TVM06 | B40: [Loại giảm giá]dropdown | E40: - Text: Black - Status: Enable | F40: - Text: Black - Status: Enable | G40: Passed | H40: 45770 | I40: Huy
A41: GUI - TVM07 | B41: [Giá trị giảm] textbox | E41: - Text: Black - Status: Enable | F41: - Text: Grey - Status: Enable | G41: Passed | H41: 45770 | I41: Huy
A42: GUI - TVM08 | B42: [Thời gian bắt đầu] datimepicker | E42: - Text: Black - Status: Enable | F42: - Text: Black - Status: Enable | G42: Passed | H42: 45771 | I42: Huy
A43: GUI - TVM09 | B43: [Thời gian kết thúc] datetimepicker | E43: - Text: Black - Status: Enable | F43: - Text: Grey - Status: Enable | G43: Passed | H43: 45772 | I43: Huy
A44: GUI - TVM10 | B44: [Danh mục áp dụng]dropdown | E44: - Text: Black - Status: Enable | F44: - Text: Black - Status: Enable | G44: Passed | H44: 45773 | I44: Huy
A45: GUI - TVM11 | B45: [Ảnh ] imagebutton | E45: - Status: Enable | F45: - Status: Enable | G45: Passed | H45: 45774 | I45: Huy
A46: GUI - TVM12 | B46: [Số lượng mã] textbox | E46: - Text: Black - Status: Enable | F46: - Text: Black - Status: Enable | G46: Passed | H46: 45775 | I46: Huy
... A50: GUI - TVM16 | B50: [Thêm mới] Button | E50: - Text: White - Background color :Green - Status: Enable | F50: - Text: White - Background color :Green - Status: Enable | G50: Passed | H50: 45779 | I50: Huy
A51: FUNCTION_SHOW Thêm voucher
A52: FUNC-TV01 | B52: Nhập đầy đủ tất cả thông tin với dữ liệu hợp lệ | C52: 1. Truy cập vào trang web 2. Nhập tất cả các trường 3. Click : "Thêm mới" | D52: Đăng nhập thành công vào hệ thống | E52: Hệ thống thông báo "Thêm mã giảm giá thành công " | F52: Hệ thống thông báo "Thêm mã giảm giá thành công " | G52: Passed | H52: 45770 | I52: Huy | J52: Passed | K52: 45987 | L52: Huy
A53: FUNC-TV02 | B53: Tên mã giảm giá chữ và số | C53: 1. Truy cập vào trang web 2. Nhập Tên mã giảm giá 3. Click : "Thêm mới" | D53: Đăng nhập thành công vào hệ thống | E53: Hệ thống thông báo "Thêm mã giảm giá thành công " | F53: Hệ thống thông báo "Thêm mã giảm giá thành công " | G53: Passed | H53: 45770 | I53: Huy | J53: Passed | K53: 45987 | L53: Huy
A54: FUNC-TV03 | B54: Ngày bắt đầu < ngày kết thúc | C54: 1. Truy cập vào trang web 2. Chọn ngày bắt đầu 3. Click : "Thêm mới" | D54: Đăng nhập thành công vào hệ thống | E54: Hệ thống thông báo "Thêm mã giảm giá thành công " | F54: Hệ thống thông báo "Thêm mã giảm giá thành công " | G54: Passed | H54: 45770 | I54: Huy | J54: Passed | K54: 45987 | L54: Huy
A55: FUNC-TV04 | B55: Bỏ trống tên mã giảm giá | C55: 1. Truy cập vào trang web 2.Để trống tên mã giảm giá 3. Click : "Thêm mới" | D55: Đăng nhập thành công vào hệ thống | E55: Hệ thống thông báo: "Mã bắt buộc" | F55: Hệ thống thông báo: "Mã bắt buộc" | G55: Passed | H55: 45770 | I55: Huy | J55: Passed | K55: 45987 | L55: Huy
A56: FUNC-TV05 | B56: Bỏ trống Mô tả | C56: 1. Truy cập vào trang web 2.Để trống mô tả 3. Click : "Thêm mới" | D56: Đăng nhập thành công vào hệ thống | E56: Hệ thống thông báo: "Mô tả bắt buộc" | F56: Hệ thống thông báo: "Mô tả bắt buộc" | G56: Passed | H56: 45770 | I56: Huy | J56: Passed | K56: 45987 | L56: Huy
A57: FUNC-TV06 | B57: Bỏ trống ngày bắt đầu | C57: 1. Truy cập vào trang web 2.Để trống ngày bất đầu 3. Click : "Thêm mới" | D57: Đăng nhập thành công vào hệ thống | E57: Hệ thống thông báo: "Thời gian bắt buộc." | F57: Hệ thống thông báo: "Thời gian bắt buộc." | G57: Passed | H57: 45770 | I57: Huy | J57: Passed | K57: 45987 | L57: Huy
A58: FUNC-TV07 | B58: Bỏ trống ngày kết thúc | C58: 1. Truy cập vào trang web 2.Để trống Ngày kết thúc 3. Click : "Thêm mới" | D58: Đăng nhập thành công vào hệ thống | E58: Hệ thống thông báo: "Thời gian bắt buộc." | F58: Hệ thống thông báo: "Thời gian bắt buộc." | G58: Passed | H58: 45770 | I58: Huy | J58: Passed | K58: 45987 | L58: Huy
A59: FUNC-TV08 | B59: Hệ thống thông báo khi ngày kết thúc nhỏ hơn ngày bắt đầu | C59: 1. Truy cập vào trang web 2. Chọn ngày bắt đầu 3. Click : "Thêm mới" | D59: Đăng nhập thành công vào hệ thống | E59: Hệ thống thông báo: "Thời gian thời gian kết thúc lớn hơn thời gian bắt đầu." | F59: Hệ thống thông báo: "Thời gian thời gian kết thúc lớn hơn thời gian bắt đầu." | G59: Passed | H59: 45770 | I59: Huy | J59: Passed | K59: 45987 | L59: Huy
A60: FUNC-TV09 | B60: Bỏ trống giá trị giảm | C60: 1. Truy cập vào trang web 2.Để trống tên mã giảm giá 3. Click : "Thêm mới" | D60: Đăng nhập thành công vào hệ thống | E60: Hệ thống thông báo: "Giá trị giảm bắt buộc." | F60: Hệ thống thông báo: "Giá trị giảm bắt buộc." | G60: Passed | H60: 45770 | I60: Huy | J60: Passed | K60: 45987 | L60: Huy
A61: FUNC-TV10 | B61: Bỏ trống số lượng mã | C61: 1. Truy cập vào trang web 2.Để trống số lượng mã 3. Click : "Thêm mới" | D61: Đăng nhập thành công vào hệ thống | E61: Hệ thống thông báo: "Số lượng giảm bắt buộc." | F61: Hệ thống thông báo: "Số lượng giảm bắt buộc." | G61: Passed | H61: 45771 | I61: Huy | J61: Passed | K61: 45987 | L61: Huy
A62: FUNC-TV11 | B62: Bỏ trống số lượt dùng | C62: 1. Truy cập vào trang web 2.Để trống số lượt dùng 3. Click : "Thêm mới" | D62: Đăng nhập thành công vào hệ thống | E62: Hệ thống thông báo: "Số lượt dùng bắt buộc." | F62: Hệ thống thông báo: "Số lượt dùng bắt buộc." | G62: Passed | H62: 45772 | I62: Huy | J62: Passed | K62: 45987 | L62: Huy
A63: FUNC-TV12 | B63: Bỏ trống giá trị tối thiểu | C63: 1. Truy cập vào trang web 2.Để trống giá trị tối thiểu 3. Click : "Thêm mới" | D63: Đăng nhập thành công vào hệ thống | E63: Hệ thống thông báo: "Giá trị tối thiểu bắt buộc." | F63: Hệ thống thông báo: "Giá trị tối thiểu bắt buộc." | G63: Passed | H63: 45773 | I63: Huy | J63: Passed | K63: 45987 | L63: Huy
... A66: FUNC-TV15 | B66: Kiểm tra tình trạng voucher khi thêm voucher thành công | C66: 1. Truy cập vào trang web 2.Điền thông tin đầy đủ 3. Click : "Thêm mới" | D66: Đăng nhập thành công vào hệ thống | E66: Tình trạng khuyến mãi được cập nhật khi thêm mới voucher | F66: Tình trạng khuyến mãi không được cập nhật khi thêm mới voucher | G66: Failed | H66: 45776 | I66: Huy | J66: Passed | K66: 45987 | L66: Huy

Sheet Danh sách danh mục
A1: Project Name | B1: XÂY DỰNG HỆ THỐNG QUẢN LÝ VÀ KIỂM DUYỆT VĂN BẢN TÍCH HỢP CHỮ KÝ SỐ VỚI THUẬT TOÁN RSA
A2: Module Code | B2: Quản lý chuyên ngành
B3: Hoàn thành | C3: Lỗi | D3: Chưa kiểm tra | E3: Bị chặn | F3: Tổng lần kiểm tra
A4: Round 1 | B4: 16 | C4: 0 | D4: 0 | E4: 0 | F4: =B4 -> 16
A5: Round 2 | B5: 0 | C5: 0 | D5: 0 | E5: 0 | F5: 0
A31: Test Case ID | B31: Mô tả | C31: Quy trình | D31: Điều kiện tiên quyết | E31: Kết quả mong đợi | F31: Kết quả thực tế | G31: Kết quả | M31: Chú thích
G32: Vòng 1 | J32: Vòng 2
G33: Trạng thái | H33: Ngày kiểm tra | I33: Người kiểm tra | J33: Trạng thái | K33: Ngày kiểm tra | L33: Người kiểm tra
A34: GUI_SHOW Thêm chuyên ngành
A35: GUI - TCN01 | B35: [Danh mục] heading | E35: - Text: Black - Status: Enable | F35: - Text: Black - Status: Enable | G35: Passed | H35: 14/11/2024 | I35: Phương
A36: GUI - TCN02 | B36: [Thêm danh mục] lick | E36: - Text: Black - Status: Enable | F36: - Text: Black - Status: Enable | G36: Passed | H36: 14/11/2024 | I36: Phương
A37: GUI - TCN03 | B37: [Copy] button | E37: - Text: Black - Status: Enable | F37: - Text: Black - Status: Enable | G37: Passed | H37: 14/11/2024 | I37: Phương
A38: GUI - TCN04 | B38: [CSV] button | E38: - Text: Black - Status: Enable | F38: - Text: Black - Status: Enable | G38: Passed | H38: 14/11/2024 | I38: Phương
A39: GUI - TCN05 | B39: [Excel] button | E39: - Text: Black - Status: Enable | F39: - Text: Black - Status: Enable | G39: Passed | H39: 14/11/2024 | I39: Phương
A40: GUI - TCN06 | B40: [PDF] button | E40: - Text: Black - Status: Enable | F40: - Text: Black - Status: Enable | G40: Passed | H40: 14/11/2024 | I40: Phương
A41: GUI - TCN07 | B41: [Xóa] button | E41: - Text: White - Background-color : red - Status: Enable | F41: - Text: White - Background-color : red - Status: Enable | G41: Passed
A42: GUI - TCN08 | B42: [Sửa] button | E42: - Text: White - Background-color : yellow - Status: Enable | F42: - Text: White - Background-color : yellow - Status: Enable | G42: Passed
A43: GUI - TCN09 | B43: [Print] button | E43: - Text: Black - Status: Enable | F43: - Text: Black - Status: Enable | G43: Passed | H43: 14/11/2024 | I43: Phương
A44: FUNCTION_SHOW Thêm chuyên ngành
A45: FUNC-TCN01 | B45: Nhập từ khóa chính xác vào "search" danh sách lọc đúng kết quả | C45: 1. Truy cập vào trang web 2. Điền từ khóa | D45: Đăng nhập thành công vào hệ thống | E45: Hệ thống hiển thị đúng danh sách vừa search | F45: Hệ thống hiển thị đúng danh sách vừa search | G45: Passed | H45: 14/11/2024 | I45: Phương
A46: FUNC-TCN02 | B46: Nhập từ khóa không tồn tại thì danh sách trống | C46: 1. Truy cập vào trang web 2. Điền từ khóa | D46: Đăng nhập thành công vào hệ thống | E46: Hệ thống hiển thị danh sách trống | F46: Hệ thống hiển thị danh sách trống | G46: Passed | H46: 14/11/2024 | I46: Phương
A47: FUNC-TCN03 | B47: Tim kiếm theo tên danh mục | C47: 1. Truy cập vào trang web 2. Điền tên danh mục cần tìm | D47: Đăng nhập thành công vào hệ thống | E47: Hệ thống thông báo hiển thị danh sách theo tên danh mục vừa tìm | F47: Hệ thống thông báo hiển thị danh sách theo tên danh mục vừa tìm | G47: Passed | H47: 14/11/2024 | I47: Phương
A48: FUNC-TCN04 | B48: Tim kiếm theo mô tả | C48: 1. Truy cập vào trang web 2. Điền mô tả cần tìm | D48: Đăng nhập thành công vào hệ thống | E48: Hệ thống thông báo hiển thị danh sách theo mô tả vừa tìm | F48: Hệ thống thông báo hiển thị danh sách theo mô tả vừa tìm | G48: Passed | H48: 14/11/2024 | I48: Phương
A49: FUNC-TCN05 | B49: Tim kiếm theo trạng thái | C49: 1. Truy cập vào trang web 2. Điền trạng thái cần tìm | D49: Đăng nhập thành công vào hệ thống | E49: Hệ thống thông báo hiển thị danh sách theo trạng thái vừa tìm | F49: Hệ thống thông báo hiển thị danh sách theo trạng thái vừa tìm | G49: Passed | H49: 14/11/2024 | I49: Phương
A50: FUNC-TCN06 | B50: Nhấn nút Sửa thì đến được form sửa danh mục | C50: 1. Truy cập vào trang web 2. Click "Sửa" | D50: Đăng nhập thành công vào hệ thống | E50: Hệ thống chuyển đến form sửa danh mục | F50: Hệ thống chuyển đến form sửa danh mục | G50: Passed | H50: 14/11/2024 | I50: Phương
A51: FUNC-TCN07 | B51: Click Copy thì nội dung được sao chép vào clipboard đúng định dạng. | C51: 1. Truy cập vào trang web 2. Click "danh mục" 3. Click : "Copy" | D51: Đăng nhập thành công vào hệ thống | E51: Hệ thống sao chép vào clipboard đunág định dạng | F51: Hệ thống sao chép vào clipboard đunág định dạng | G51: Passed | H51: 14/11/2024 | I51: Phương
A52: FUNC-TCN08 | B52: Click CSV thì file tải xuống đúng định dạng .csv, có đủ cột. | C52: 1. Truy cập vào trang web 2. Click "Danh mục" 3. Click : "excel" | D52: Đăng nhập thành công vào hệ thống | E52: Hệ thống tải file xuống đúng định dạng .csv, có đủ cột. | F52: Hệ thống tải file xuống đúng định dạng .csv, có đủ cột. | G52: Passed | H52: 14/11/2024 | I52: Phương
A53: FUNC-TCN09 | B53: Click PDF thì file .pdf hiển thị đúng bảng shipping. | C53: 1. Truy cập vào trang web 2. Click "Danh mục" 3. Click : "PDF" | D53: Đăng nhập thành công vào hệ thống | E53: Hệ thống tải file .pdf hiển thị đúng bảng shipping. | F53: Hệ thống tải file .pdf hiển thị đúng bảng shipping. | G53: Passed | H53: 14/11/2024 | I53: Phương
A54: FUNC-TCN10 | B54: Click Print thì mở preview để in bảng đúng format. | C54: 1. Truy cập vào trang web 2. Click "Danh mục" 3. Click : "Print" | D54: Đăng nhập thành công vào hệ thống | E54: Hệ thống mở preview để in bảng đúng format. | F54: Hệ thống mở preview để in bảng đúng format.

Sheet Quản lý đặt hàng
A1: Project Name | B1: CoffeeGo-Nền tảng đặt bàn quán cà phê tích hợp AI Assistant và thanh toán điện tử
A2: Module Code | B2: Quản lý đặt hàng
B3: Hoàn thành | C3: Lỗi | D3: Chưa kiểm tra | E3: Bị chặn | F3: Tổng lần kiểm tra
A4: Round 1 | B4: =COUNTA(A35:A47)- 1 -> 12 | C4: =COUNTIF(G:G,"Failed") -> 0 | D4: =COUNTIF(G:G,"Untested") -> 0 | E4: =COUNTIF(G:G,"Blocked") -> 0 | F4: =B4 -> 12
A5: Round 2 | B5: =COUNTA(A43:A47) -> 5 | C5: =COUNTIF(J:J,"Failed") -> 0 | D5: =COUNTIF(J:J,"Untested") -> 0 | E5: =COUNTIF(J:J,"Blocked") -> 0 | F5: =B5 -> 5
A31: Test Case ID | B31: Mô tả | C31: Quy trình | D31: Điều kiện tiên quyết | E31: Kết quả mong đợi | F31: Kết quả thực tế | G31: Kết quả | M31: Chú thích
G32: Vòng 1 | J32: Vòng 2
G33: Trạng thái | H33: Ngày kiểm tra | I33: Người kiểm tra | J33: Trạng thái | K33: Ngày kiểm tra | L33: Người kiểm tra
A34: GUI_SHOW Danh sách đơn hàng
A35: GUI - QLDH01 | B35: [Quản lý đơn hàng] Label | C35: 1. Truy cập vào menu "Quản lý đơn hàng" | D35: Đăng nhập với vai trò Admin thành công. | E35: - Text: "Quản lý đơn hàng" (Bold, Large) - Subtitle: "Danh sách đơn hàng" (Small, Gray) - Align: Left | F35: - Text: "Quản lý đơn hàng" (Bold, Large) - Subtitle: "Danh sách đơn hàng" (Small, Gray) - Align: Left | G35: Passed | H35: 45984 | I35: Tấn
A36: GUI - QLDH02 | B36: [Tìm kiếm] Input | E36: - Placeholder: "Tìm kiếm tên khách hàng..." - Icon: Search (Kính lúp) bên trái - Border: Rounded, Gray - Status: Enable | F36: - Placeholder: "Tìm kiếm tên khách hàng..." - Icon: Search (Kính lúp) bên trái - Border: Rounded, Gray - Status: Enable | G36: Passed | H36: 45984 | I36: Tấn
A37: GUI - QLDH03 | B37: [Chi tiết đơn hàng]Icon | E37: -Status : Enable -Background-color : Red | F37: -Status : Enable -Background-color : Red | G37: Passed | H37: 45984 | I37: Tấn
A38: GUI - QLDH04 | B38: [Xác nhận đơn hàng]Icon | E38: -Status : Enable -Background-color : Green | F38: -Status : Enable -Background-color : Green | G38: Passed | H38: 45984 | I38: Tấn
A39: GUI - QLDH05 | B39: [Phân trang/Danh sách đơn hàng] Table | E39: - Các dòng có màu nền xen kẽ hoặc đường kẻ ngang phân cách rõ ràng (Border-bottom) - Không bị vỡ khung khi thay đổi kích thước màn hình | F39: - Các dòng có màu nền xen kẽ hoặc đường kẻ ngang phân cách rõ ràng (Border-bottom) - Không bị vỡ khung khi thay đổi kích thước màn hình | G39: Passed | H39: 45984 | I39: Tấn
A40: FUNCTION_SHOW Danh sách đơn hàng
A41: FUNC-QLDH01 | B41: Tìm kiếm theo tên khách hàng hợp lệ (Có kết quả) | C41: 1. Truy cập trang Quản lý đơn hàng. 2. Click vào ô tìm kiếm. 3. Nhập từ khóa "huy" | D41: Đăng nhập với vai trò Admin thành công. | E41: Hệ thống hiển thị danh sách đơn hàng lọc đúng theo tên "huy". | F41: Hệ thống lọc và hiển thị đơn hàng của khách hàng tên "huy". | G41: Passed | H41: 45984 | I41: Tấn | J41: Passed | K41: 45987 | L41: Tấn
A42: FUNC-QLDH02 | B42: Tìm kiếm theo tên khách hàng không tồn tại | C42: 1. Truy cập trang Quản lý đơn hàng. 2. Nhập từ khóa "người lạ" vào ô tìm kiếm. | D42: Đăng nhập với vai trò Admin thành công. | E42: Hệ thống hiển thị danh sách trống hoặc thông báo không tìm thấy. | F42: Hệ thống hiển thị danh sách trống, không có dữ liệu. | G42: Passed | H42: 45984 | I42: Tấn | J42: Passed | K42: 45987 | L42: Tấn
A43: FUNC-QLDH03 | B43: Tìm kiếm với từ khóa để trống (Hiển thị tất cả) | C43: 1. Đang có kết quả lọc. 2. Xóa trắng ô tìm kiếm. | D43: Đăng nhập với vai trò Admin thành công. | E43: Hệ thống tải lại và hiển thị toàn bộ danh sách đơn hàng ban đầu. | F43: Hệ thống hiển thị lại toàn bộ danh sách đơn hàng. | G43: Passed | H43: 45984 | I43: Tấn | J43: Passed | K43: 45987 | L43: Tấn
A44: FUNC-QLDH04 | B44: Click icon "Mắt" xem chi tiết đơn hàng (Thành công) | C44: 1. Tìm đơn hàng bất kỳ tình trạng hoàn tất 2. Click vào icon con mắt (Action). | D44: Đăng nhập với vai trò Admin thành công. | E44: Hệ thống mở Popup chi tiết đơn hàng đúng với đơn vừa bấm vào | F44: Popup hiển thị đúng thông tin của đơn vừa bấm vào | G44: Passed | H44: 45984 | I44: Tấn | J44: Passed | K44: 45987 | L44: Tấn
A45: FUNC-QLDH05 | B45: Click icon "Mắt" xem chi tiết đơn hàng (Đã hủy) | C45: 1. Tìm đơn hàng tình trạng thất bại 2. Click vào icon con mắt. | D45: Đăng nhập với vai trò Admin thành công. | E45: Hệ thống mở Popup chi tiết đơn hàng đúng với đơn vừa bấm vào | F45: Popup hiển thị đúng thông tin của đơn vừa bấm vào | G45: Passed | H45: 45984 | I45: Tấn | J45: Passed | K45: 45987 | L45: Tấn
A46: FUNC-QLDH06 | B46: Kiểm tra hiển thị trạng thái "Hoàn tất" | C46: 1. Truy cập trang quản lý đơn hàng 2. Quan sát cột "Tình trạng thanh toán". | D46: Đăng nhập với vai trò Admin thành công. | E46: Đơn "Hoàn tất" phải hiển thị chữ màu xanh lá cây. | F46: Chữ "Hoàn tất" hiển thị màu xanh lá cây đúng thiết kế. | G46: Passed | H46: 45984 | I46: Tấn | J46: Passed | K46: 45987 | L46: Tấn
A47: FUNC-QLDH07 | B47: Kiểm tra hiển thị trạng thái "Thất bại" | C47: 1. Truy cập trang quản lý đơn hàng 2. Quan sát cột "Tình trạng thanh toán". | D47: Đăng nhập với vai trò Admin thành công. | E47: Đơn "Thất bại" phải hiển thị chữ màu đỏ. | F47: Chữ "Thất bại" hiển thị màu đỏ đúng thiết kế. | G47: Passed | H47: 45984 | I47: Tấn | J47: Passed | K47: 45987 | L47: Tấn
A48: FUNC-QLDH08 | B48: Kiểm tra sắp xếp thứ tự đơn hàng (Mặc định) | C48: 1. Truy cập trang quản lý đơn hàng 2. So sánh cột "Thời gian" giữa các dòng. | D48: Đăng nhập với vai trò Admin thành công. | E48: Đơn hàng mới nhất (thời gian gần nhất) hiển thị trên cùng. | F48: Đơn hàng 21:08 nằm trên đơn 20:54. Sắp xếp đúng. | G48: Passed | H48: 45984 | I48: Tấn | J48: Passed | K48: 45987 | L48: Tấn
A49: FUNC-QLDH09 | B49: Kiểm tra định dạng tiền tệ | C49: 1. Quan sát cột "Tổng tiền". | D49: Đăng nhập với vai trò Admin thành công. | E49: Số tiền có dấu chấm phân cách hàng nghìn (VD: 100.000 đ). | F49: Hiển thị đúng format: 100.000 đ, 120.000 đ. | G49: Passed | H49: 45984 | I49: Tấn | J49: Passed | K49: 45987 | L49: Tấn
A50: FUNC-QLDH10 | B50: Kiểm tra hiển thị đơn hàng có nhiều món | C50: 1. Tìm đơn hàng có nhiều món (VD: đơn #f8a49d98). 2. Quan sát cột "Sản phẩm". | D50: Đăng nhập với vai trò Admin thành công. | E50: Ô sản phẩm hiển thị đủ tên món và số lượng, không bị tràn khung. | F50: Hiển thị đủ thông tin, tự động xuống dòng hợp lý. | G50: Passed | H50: 45984 | I50: Tấn | J50: Passed | K50: 45987 | L50: Tấn
A51: FUNC-QLDH11 | B51: Kiểm tra hiển thị trạng thái đơn "Đang xử lý" | C51: 1. Tìm đơn hàng bất kỳ đang xử lý 2. Quan sát cột "Tình trạng đơn hàng". | D51: Admin đã đăng nhập. Đơn hàng mới được đặt, đã thanh toán | E51: Badge "Đang xử lý" ở tình trạng đơn hàng hiển thị nền màu vàng nhạt, | F51: Badge "Đang xử lý" ở tình trạng đơn hàng hiển thị nền màu vàng nhạt, | G51: Passed | H51: 45984 | I51: Tấn | J51: Passed | K51: 45987 | L51: Tấn
A52: FUNC-QLDH12 | B52: Kiểm tra hiển thị thanh toán "Đang chờ" | C52: 1. Tìm đơn hàng chưa thanh toán 2. Quan sát cột "Tình trạng thanh toán". | D52: Admin đã đăng nhập. Đơn chưa thanh toán. | E52: Chữ "Đang chờ" ở chỗ tình trạng thanh toán, hiển thị màu cam | F52: Chữ "Đang chờ" ở chỗ tình trạng thanh toán, hiển thị màu cam | G52: Passed | H52: 45984 | I52: Tấn | J52: Passed | K52: 45987 | L52: Tấn
... A57: FUNC-QLDH17 | B57: Kiểm tra nút xác nhận hoàn thành, hủy cho đơn đã thanh toán | C57: 1. Ấn vào hình con mắt ở đơn hàng đã thanh toán 2. Ấn vào nút duyệt đơn ( icon xanh ) | D57: Đăng nhập với vai trò Admin thành công. | E57: Nhấn xác nhận hoàn thành, đơn hàng sẽ chuyển trạng thái sang hoàn tất Nhấn hủy, sẽ tắt GUI xác nhận đơn hàng | F57: Nhấn xác nhận hoàn thành, đơn hàng sẽ chuyển trạng thái sang hoàn tất Nhấn hủy, sẽ tắt GUI xác nhận đơn hàng | G57: Passed | H57: 45984 | I57: Tấn | J57: Passed | K57: 45987 | L57: Tấn

Sheet Thống kê 
A1: Project Name | B1: CoffeeGo-Nền tảng đặt bàn quán cà phê tích hợp AI Assistant và thanh toán điện tử
A2: Module Code | B2: Thống kê
B3: Hoàn thành | C3: Lỗi | D3: Chưa kiểm tra | E3: Bị chặn | F3: Tổng lần kiểm tra
A4: Round 1 | B4: =COUNTA(A35:A47)- 1 -> 12 | C4: =COUNTIF(G:G,"Failed") -> 3 | D4: =COUNTIF(G:G,"Untested") -> 0 | E4: =COUNTIF(G:G,"Blocked") -> 0 | F4: =B4 -> 12
A5: Round 2 | B5: =COUNTA(A43:A47) -> 5 | C5: =COUNTIF(J:J,"Failed") -> 0 | D5: =COUNTIF(J:J,"Untested") -> 0 | E5: =COUNTIF(J:J,"Blocked") -> 0 | F5: =B5 -> 5
